Workbook
Name Slicer_Broad_Categories: #N/A

Sheet All_India_Index_Upto_April23__1
A1: Sector | B1: Year | C1: Month | D1: General index | E1: Categories | F1: Value | G1: Broad Categories
A2: Rural | B2: 2013 | C2: January | D2: 105.1 | E2: Cereals and products | F2: 107.5 | G2: =VLOOKUP(All_India_Index_Upto_April23__1_1[[#This Row],[Categories]],'Broad Categroies'!$A$1:$B$27,2,FALSE) -> Food And Beverages
A3: Rural | B3: 2013 | C3: January | D3: 105.1 | E3: Meat and fish | F3: 106.3 | G3: =VLOOKUP(All_India_Index_Upto_April23__1_1[[#This Row],[Categories]],'Broad Categroies'!$A$1:$B$27,2,FALSE) -> Food And Beverages
A4: Rural | B4: 2013 | C4: January | D4: 105.1 | E4: Egg | F4: 108.1 | G4: =VLOOKUP(All_India_Index_Upto_April23__1_1[[#This Row],[Categories]],'Broad Categroies'!$A$1:$B$27,2,FALSE) -> Food And Beverages
A5: Rural | B5: 2013 | C5: January | D5: 105.1 | E5: Milk and products | F5: 104.9 | G5: =VLOOKUP(All_India_Index_Upto_April23__1_1[[#This Row],[Categories]],'Broad Categroies'!$A$1:$B$27,2,FALSE) -> Food And Beverages
A6: Rural | B6: 2013 | C6: January | D6: 105.1 | E6: Oils and fats | F6: 106.1 | G6: =VLOOKUP(All_India_Index_Upto_April23__1_1[[#This Row],[Categories]],'Broad Categroies'!$A$1:$B$27,2,FALSE) -> Food And Beverages
A7: Rural | B7: 2013 | C7: January | D7: 105.1 | E7: Fruits | F7: 103.9 | G7: =VLOOKUP(All_India_Index_Upto_April23__1_1[[#This Row],[Categories]],'Broad Categroies'!$A$1:$B$27,2,FALSE) -> Food And Beverages
A8: Rural | B8: 2013 | C8: January | D8: 105.1 | E8: Vegetables | F8: 101.9 | G8: =VLOOKUP(All_India_Index_Upto_April23__1_1[[#This Row],[Categories]],'Broad Categroies'!$A$1:$B$27,2,FALSE) -> Food And Beverages
A9: Rural | B9: 2013 | C9: January | D9: 105.1 | E9: Pulses and products | F9: 106.1 | G9: =VLOOKUP(All_India_Index_Upto_April23__1_1[[#This Row],[Categories]],'Broad Categroies'!$A$1:$B$27,2,FALSE) -> Food And Beverages
A10: Rural | B10: 2013 | C10: January | D10: 105.1 | E10: Sugar and Confectionery | F10: 106.8 | G10: =VLOOKUP(All_India_Index_Upto_April23__1_1[[#This Row],[Categories]],'Broad Categroies'!$A$1:$B$27,2,FALSE) -> Food And Beverages
A11: Rural | B11: 2013 | C11: January | D11: 105.1 | E11: Spices | F11: 103.1 | G11: =VLOOKUP(All_India_Index_Upto_April23__1_1[[#This Row],[Categories]],'Broad Categroies'!$A$1:$B$27,2,FALSE) -> Food And Beverages
A12: Rural | B12: 2013 | C12: January | D12: 105.1 | E12: Non-alcoholic beverages | F12: 104.8 | G12: =VLOOKUP(All_India_Index_Upto_April23__1_1[[#This Row],[Categories]],'Broad Categroies'!$A$1:$B$27,2,FALSE) -> Food And Beverages
A13: Rural | B13: 2013 | C13: January | D13: 105.1 | E13: Prepared meals, snacks, sweets etc. | F13: 106.7 | G13: =VLOOKUP(All_India_Index_Upto_April23__1_1[[#This Row],[Categories]],'Broad Categroies'!$A$1:$B$27,2,FALSE) -> Food And Beverages
... A18: Rural | B18: 2013 | C18: January | D18: 105.1 | E18: Clothing and footwear | F18: 106.4 | G18: =VLOOKUP(All_India_Index_Upto_April23__1_1[[#This Row],[Categories]],'Broad Categroies'!$A$1:$B$27,2,FALSE) -> Clothing and Footwear
A19: Rural | B19: 2013 | C19: January | D19: 105.1 | E19: Housing | G19: =VLOOKUP(All_India_Index_Upto_April23__1_1[[#This Row],[Categories]],'Broad Categroies'!$A$1:$B$27,2,FALSE) -> Housing
A20: Rural | B20: 2013 | C20: January | D20: 105.1 | E20: Fuel and light | F20: 105.5 | G20: =VLOOKUP(All_India_Index_Upto_April23__1_1[[#This Row],[Categories]],'Broad Categroies'!$A$1:$B$27,2,FALSE) -> Fuel and Light
A21: Rural | B21: 2013 | C21: January | D21: 105.1 | E21: Household goods and services | F21: 104.8 | G21: =VLOOKUP(All_India_Index_Upto_April23__1_1[[#This Row],[Categories]],'Broad Categroies'!$A$1:$B$27,2,FALSE) -> Household Goods/Services
A22: Rural | B22: 2013 | C22: January | D22: 105.1 | E22: Health | F22: 104 | G22: =VLOOKUP(All_India_Index_Upto_April23__1_1[[#This Row],[Categories]],'Broad Categroies'!$A$1:$B$27,2,FALSE) -> Health
A23: Rural | B23: 2013 | C23: January | D23: 105.1 | E23: Transport and communication | F23: 103.3 | G23: =VLOOKUP(All_India_Index_Upto_April23__1_1[[#This Row],[Categories]],'Broad Categroies'!$A$1:$B$27,2,FALSE) -> Transport and Communication
A24: Rural | B24: 2013 | C24: January | D24: 105.1 | E24: Recreation and amusement | F24: 103.4 | G24: =VLOOKUP(All_India_Index_Upto_April23__1_1[[#This Row],[Categories]],'Broad Categroies'!$A$1:$B$27,2,FALSE) -> Recreation and Amusement
A25: Rural | B25: 2013 | C25: January | D25: 105.1 | E25: Education | F25: 103.8 | G25: =VLOOKUP(All_India_Index_Upto_April23__1_1[[#This Row],[Categories]],'Broad Categroies'!$A$1:$B$27,2,FALSE) -> Education
A26: Rural | B26: 2013 | C26: January | D26: 105.1 | E26: Personal care and effects | F26: 104.7 | G26: =VLOOKUP(All_India_Index_Upto_April23__1_1[[#This Row],[Categories]],'Broad Categroies'!$A$1:$B$27,2,FALSE) -> Personal Care/Effects
A27: Rural | B27: 2013 | C27: January | D27: 105.1 | E27: Miscellaneous | F27: 104 | G27: =VLOOKUP(All_India_Index_Upto_April23__1_1[[#This Row],[Categories]],'Broad Categroies'!$A$1:$B$27,2,FALSE) -> Miscellaneous
A28: Urban | B28: 2013 | C28: January | D28: 104 | E28: Cereals and products | F28: 110.5 | G28: =VLOOKUP(All_India_Index_Upto_April23__1_1[[#This Row],[Categories]],'Broad Categroies'!$A$1:$B$27,2,FALSE) -> Food And Beverages
A29: Urban | B29: 2013 | C29: January | D29: 104 | E29: Meat and fish | F29: 109.1 | G29: =VLOOKUP(All_India_Index_Upto_April23__1_1[[#This Row],[Categories]],'Broad Categroies'!$A$1:$B$27,2,FALSE) -> Food And Beverages
A30: Urban | B30: 2013 | C30: January | D30: 104 | E30: Egg | F30: 113 | G30: =VLOOKUP(All_India_Index_Upto_April23__1_1[[#This Row],[Categories]],'Broad Categroies'!$A$1:$B$27,2,FALSE) -> Food And Beverages
A31: Urban | B31: 2013 | C31: January | D31: 104 | E31: Milk and products | F31: 103.6 | G31: =VLOOKUP(All_India_Index_Upto_April23__1_1[[#This Row],[Categories]],'Broad Categroies'!$A$1:$B$27,2,FALSE) -> Food And Beverages
... A96: Rural | B96: 2013 | C96: February | D96: 105.8 | E96: Clothing and footwear | F96: 107 | G96: =VLOOKUP(All_India_Index_Upto_April23__1_1[[#This Row],[Categories]],'Broad Categroies'!$A$1:$B$27,2,FALSE) -> Clothing and Footwear
A97: Rural | B97: 2013 | C97: February | D97: 105.8 | E97: Housing | G97: =VLOOKUP(All_India_Index_Upto_April23__1_1[[#This Row],[Categories]],'Broad Categroies'!$A$1:$B$27,2,FALSE) -> Housing
A98: Rural | B98: 2013 | C98: February | D98: 105.8 | E98: Fuel and light | F98: 106.2 | G98: =VLOOKUP(All_India_Index_Upto_April23__1_1[[#This Row],[Categories]],'Broad Categroies'!$A$1:$B$27,2,FALSE) -> Fuel and Light
A99: Rural | B99: 2013 | C99: February | D99: 105.8 | E99: Household goods and services | F99: 105.2 | G99: =VLOOKUP(All_India_Index_Upto_April23__1_1[[#This Row],[Categories]],'Broad Categroies'!$A$1:$B$27,2,FALSE) -> Household Goods/Services
A100: Rural | B100: 2013 | C100: February | D100: 105.8 | E100: Health | F100: 104.4 | G100: =VLOOKUP(All_India_Index_Upto_April23__1_1[[#This Row],[Categories]],'Broad Categroies'!$A$1:$B$27,2,FALSE) -> Health
A101: Rural | B101: 2013 | C101: February | D101: 105.8 | E101: Transport and communication | F101: 103.9 | G101: =VLOOKUP(All_India_Index_Upto_April23__1_1[[#This Row],[Categories]],'Broad Categroies'!$A$1:$B$27,2,FALSE) -> Transport and Communication
A102: Rural | B102: 2013 | C102: February | D102: 105.8 | E102: Recreation and amusement | F102: 104 | G102: =VLOOKUP(All_India_Index_Upto_April23__1_1[[#This Row],[Categories]],'Broad Categroies'!$A$1:$B$27,2,FALSE) -> Recreation and Amusement
A103: Rural | B103: 2013 | C103: February | D103: 105.8 | E103: Education | F103: 104.1 | G103: =VLOOKUP(All_India_Index_Upto_April23__1_1[[#This Row],[Categories]],'Broad Categroies'!$A$1:$B$27,2,FALSE) -> Education
A104: Rural | B104: 2013 | C104: February | D104: 105.8 | E104: Personal care and effects | F104: 104.6 | G104: =VLOOKUP(All_India_Index_Upto_April23__1_1[[#This Row],[Categories]],'Broad Categroies'!$A$1:$B$27,2,FALSE) -> Personal Care/Effects
A105: Rural | B105: 2013 | C105: February | D105: 105.8 | E105: Miscellaneous | F105: 104.4 | G105: =VLOOKUP(All_India_Index_Upto_April23__1_1[[#This Row],[Categories]],'Broad Categroies'!$A$1:$B$27,2,FALSE) -> Miscellaneous
A106: Urban | B106: 2013 | C106: February | D106: 104.7 | E106: Cereals and products | F106: 112.9 | G106: =VLOOKUP(All_India_Index_Upto_April23__1_1[[#This Row],[Categories]],'Broad Categroies'!$A$1:$B$27,2,FALSE) -> Food And Beverages
A107: Urban | B107: 2013 | C107: February | D107: 104.7 | E107: Meat and fish | F107: 112.9 | G107: =VLOOKUP(All_India_Index_Upto_April23__1_1[[#This Row],[Categories]],'Broad Categroies'!$A$1:$B$27,2,FALSE) -> Food And Beverages
A108: Urban | B108: 2013 | C108: February | D108: 104.7 | E108: Egg | F108: 116.9 | G108: =VLOOKUP(All_India_Index_Upto_April23__1_1[[#This Row],[Categories]],'Broad Categroies'!$A$1:$B$27,2,FALSE) -> Food And Beverages
...

Sheet Broad Categroies
A1: Categories | B1: Broad Categories
A2: Cereals and products | B2: Food And Beverages
A3: Meat and fish | B3: Food And Beverages
A4: Egg | B4: Food And Beverages
A5: Milk and products | B5: Food And Beverages
A6: Oils and fats | B6: Food And Beverages
A7: Fruits | B7: Food And Beverages
A8: Vegetables | B8: Food And Beverages
A9: Pulses and products | B9: Food And Beverages
A10: Sugar and Confectionery | B10: Food And Beverages
A11: Spices | B11: Food And Beverages
A12: Non-alcoholic beverages | B12: Food And Beverages
... A22: Health | B22: Health
A23: Transport and communication | B23: Transport and Communication | E23: w
A24: Recreation and amusement | B24: Recreation and Amusement
A25: Education | B25: Education
A26: Personal care and effects | B26: Personal Care/Effects
A27: Miscellaneous | B27: Miscellaneous

Sheet Helper
A1: Sector | B1: Year | C1: Month | D1: General index | E1: Categories | F1: Value | G1: Broad Categories
A2: Rural | B2: 2013 | C2: January | D2: 105.1 | E2: Cereals and products | F2: 107.5 | G2: Food And Beverages
A3: Rural | B3: 2013 | C3: January | D3: 105.1 | E3: Meat and fish | F3: 106.3 | G3: Food And Beverages
A4: Rural | B4: 2013 | C4: January | D4: 105.1 | E4: Egg | F4: 108.1 | G4: Food And Beverages
A5: Rural | B5: 2013 | C5: January | D5: 105.1 | E5: Milk and products | F5: 104.9 | G5: Food And Beverages
A6: Rural | B6: 2013 | C6: January | D6: 105.1 | E6: Oils and fats | F6: 106.1 | G6: Food And Beverages
A7: Rural | B7: 2013 | C7: January | D7: 105.1 | E7: Fruits | F7: 103.9 | G7: Food And Beverages
A8: Rural | B8: 2013 | C8: January | D8: 105.1 | E8: Vegetables | F8: 101.9 | G8: Food And Beverages
A9: Rural | B9: 2013 | C9: January | D9: 105.1 | E9: Pulses and products | F9: 106.1 | G9: Food And Beverages
A10: Rural | B10: 2013 | C10: January | D10: 105.1 | E10: Sugar and Confectionery | F10: 106.8 | G10: Food And Beverages
A11: Rural | B11: 2013 | C11: January | D11: 105.1 | E11: Spices | F11: 103.1 | G11: Food And Beverages
A12: Rural | B12: 2013 | C12: January | D12: 105.1 | E12: Non-alcoholic beverages | F12: 104.8 | G12: Food And Beverages
A13: Rural | B13: 2013 | C13: January | D13: 105.1 | E13: Prepared meals, snacks, sweets etc. | F13: 106.7 | G13: Food And Beverages
... A18: Rural | B18: 2013 | C18: January | D18: 105.1 | E18: Clothing and footwear | F18: 106.4 | G18: Clothing and Footwear
A19: Rural | B19: 2013 | C19: January | D19: 105.1 | E19: Housing | G19: Housing
A20: Rural | B20: 2013 | C20: January | D20: 105.1 | E20: Fuel and light | F20: 105.5 | G20: Fuel and Light
A21: Rural | B21: 2013 | C21: January | D21: 105.1 | E21: Household goods and services | F21: 104.8 | G21: Household Goods/Services
A22: Rural | B22: 2013 | C22: January | D22: 105.1 | E22: Health | F22: 104 | G22: Health
A23: Rural | B23: 2013 | C23: January | D23: 105.1 | E23: Transport and communication | F23: 103.3 | G23: Transport and Communication
A24: Rural | B24: 2013 | C24: January | D24: 105.1 | E24: Recreation and amusement | F24: 103.4 | G24: Recreation and Amusement
A25: Rural | B25: 2013 | C25: January | D25: 105.1 | E25: Education | F25: 103.8 | G25: Education
A26: Rural | B26: 2013 | C26: January | D26: 105.1 | E26: Personal care and effects | F26: 104.7 | G26: Personal Care/Effects
A27: Rural | B27: 2013 | C27: January | D27: 105.1 | E27: Miscellaneous | F27: 104 | G27: Miscellaneous
A28: Urban | B28: 2013 | C28: January | D28: 104 | E28: Cereals and products | F28: 110.5 | G28: Food And Beverages
A29: Urban | B29: 2013 | C29: January | D29: 104 | E29: Meat and fish | F29: 109.1 | G29: Food And Beverages
A30: Urban | B30: 2013 | C30: January | D30: 104 | E30: Egg | F30: 113 | G30: Food And Beverages
A31: Urban | B31: 2013 | C31: January | D31: 104 | E31: Milk and products | F31: 103.6 | G31: Food And Beverages
... A96: Rural | B96: 2013 | C96: February | D96: 105.8 | E96: Clothing and footwear | F96: 107 | G96: Clothing and Footwear
A97: Rural | B97: 2013 | C97: February | D97: 105.8 | E97: Housing | G97: Housing
A98: Rural | B98: 2013 | C98: February | D98: 105.8 | E98: Fuel and light | F98: 106.2 | G98: Fuel and Light
A99: Rural | B99: 2013 | C99: February | D99: 105.8 | E99: Household goods and services | F99: 105.2 | G99: Household Goods/Services
A100: Rural | B100: 2013 | C100: February | D100: 105.8 | E100: Health | F100: 104.4 | G100: Health
A101: Rural | B101: 2013 | C101: February | D101: 105.8 | E101: Transport and communication | F101: 103.9 | G101: Transport and Communication
A102: Rural | B102: 2013 | C102: February | D102: 105.8 | E102: Recreation and amusement | F102: 104 | G102: Recreation and Amusement
A103: Rural | B103: 2013 | C103: February | D103: 105.8 | E103: Education | F103: 104.1 | G103: Education
A104: Rural | B104: 2013 | C104: February | D104: 105.8 | E104: Personal care and effects | F104: 104.6 | G104: Personal Care/Effects
A105: Rural | B105: 2013 | C105: February | D105: 105.8 | E105: Miscellaneous | F105: 104.4 | G105: Miscellaneous
A106: Urban | B106: 2013 | C106: February | D106: 104.7 | E106: Cereals and products | F106: 112.9 | G106: Food And Beverages
A107: Urban | B107: 2013 | C107: February | D107: 104.7 | E107: Meat and fish | F107: 112.9 | G107: Food And Beverages
A108: Urban | B108: 2013 | C108: February | D108: 104.7 | E108: Egg | F108: 116.9 | G108: Food And Beverages
...

Sheet Q1 Helper
A1: Sector | B1: Year | C1: Month | D1: General index | E1: Categories | F1: Value | G1: Broad Categories
A2: Rural | B2: 2023 | C2: May | D2: 179.8 | E2: Cereals and products | F2: 173.2 | G2: Food And Beverages
A3: Rural | B3: 2023 | C3: May | D3: 179.8 | E3: Meat and fish | F3: 211.5 | G3: Food And Beverages
A4: Rural | B4: 2023 | C4: May | D4: 179.8 | E4: Egg | F4: 171 | G4: Food And Beverages
A5: Rural | B5: 2023 | C5: May | D5: 179.8 | E5: Milk and products | F5: 179.6 | G5: Food And Beverages
A6: Rural | B6: 2023 | C6: May | D6: 179.8 | E6: Oils and fats | F6: 173.3 | G6: Food And Beverages
A7: Rural | B7: 2023 | C7: May | D7: 179.8 | E7: Fruits | F7: 169 | G7: Food And Beverages
A8: Rural | B8: 2023 | C8: May | D8: 179.8 | E8: Vegetables | F8: 148.7 | G8: Food And Beverages
A9: Rural | B9: 2023 | C9: May | D9: 179.8 | E9: Pulses and products | F9: 174.9 | G9: Food And Beverages
A10: Rural | B10: 2023 | C10: May | D10: 179.8 | E10: Sugar and Confectionery | F10: 121.9 | G10: Food And Beverages
A11: Rural | B11: 2023 | C11: May | D11: 179.8 | E11: Spices | F11: 221 | G11: Food And Beverages
A12: Rural | B12: 2023 | C12: May | D12: 179.8 | E12: Non-alcoholic beverages | F12: 178.7 | G12: Food And Beverages
A13: Rural | B13: 2023 | C13: May | D13: 179.8 | E13: Prepared meals, snacks, sweets etc. | F13: 191.1 | G13: Food And Beverages
... A18: Rural | B18: 2023 | C18: May | D18: 179.8 | E18: Clothing and footwear | F18: 190.8 | G18: Clothing and Footwear
A19: Rural | B19: 2023 | C19: May | D19: 179.8 | E19: Housing | G19: Housing
A20: Rural | B20: 2023 | C20: May | D20: 179.8 | E20: Fuel and light | F20: 182.5 | G20: Fuel and Light
A21: Rural | B21: 2023 | C21: May | D21: 179.8 | E21: Household goods and services | F21: 179.8 | G21: Household Goods/Services
A22: Rural | B22: 2023 | C22: May | D22: 179.8 | E22: Health | F22: 187.8 | G22: Health
A23: Rural | B23: 2023 | C23: May | D23: 179.8 | E23: Transport and communication | F23: 169.7 | G23: Transport and Communication
A24: Rural | B24: 2023 | C24: May | D24: 179.8 | E24: Recreation and amusement | F24: 173.8 | G24: Recreation and Amusement
A25: Rural | B25: 2023 | C25: May | D25: 179.8 | E25: Education | F25: 180.3 | G25: Education
A26: Rural | B26: 2023 | C26: May | D26: 179.8 | E26: Personal care and effects | F26: 184.9 | G26: Personal Care/Effects
A27: Rural | B27: 2023 | C27: May | D27: 179.8 | E27: Miscellaneous | F27: 179.5 | G27: Miscellaneous
A28: Urban | B28: 2023 | C28: May | D28: 178.2 | E28: Cereals and products | F28: 174.7 | G28: Food And Beverages
A29: Urban | B29: 2023 | C29: May | D29: 178.2 | E29: Meat and fish | F29: 219.4 | G29: Food And Beverages
A30: Urban | B30: 2023 | C30: May | D30: 178.2 | E30: Egg | F30: 176.7 | G30: Food And Beverages
A31: Urban | B31: 2023 | C31: May | D31: 178.2 | E31: Milk and products | F31: 179.4 | G31: Food And Beverages
... A79: Rural+Urban | B79: 2023 | C79: May | D79: 179.1 | E79: Miscellaneous | F79: 175.7 | G79: Miscellaneous

Sheet Q1
A1: Based on the latest month's data, identify the contribution of different broader categories (food, energy, transportation, education, etc.) towards the CPI basket. Broader categories (buckets) can be created by combining similar categories into one bucket; Ex.: Meals, Beverages, Cereals, can be clubbed to create "Food" category, etc.
A10: Year | B10: 2023
A11: Month | B11: May
A13: Row Labels | B13: Sum of Value
A14: Food And Beverages | B14: 0.50258444
A15: Clothing and Footwear | B15: 0.11974685
A16: Tobacco and Intoxicants | B16: 0.043866581
A17: Health | B17: 0.040285339
A18: Personal Care/Effects | B18: 0.040285339
A19: Fuel and Light | B19: 0.039777876
A20: Education | B20: 0.038581712
A21: Miscellaneous | B21: 0.038190241
A22: Household Goods/Services | B22: 0.038067
A23: Recreation and Amusement | B23: 0.037276807
A24: Transport and Communication | B24: 0.035877658
A25: Housing | B25: 0.025460161
A26: Grand Total | B26: 1

Sheet Q2
A1: A trend of Y-o-Y increase in CPI (rural + urban) inflation starting 2017 for the entire basket of products combined.
A2: Sector | B2: Year | C2: Month | D2: General index | E2: Categories | F2: Value | G2: Broad Categories | H2: YoY % Increase
A3: Rural+Urban | B3: 2016 | C3: January | D3: 126.3 | E3: Cereals and products | F3: 126.1 | G3: Food And Beverages
A4: Rural+Urban | B4: 2016 | C4: January | D4: 126.3 | E4: Meat and fish | F4: 134.1 | G4: Food And Beverages
A5: Rural+Urban | B5: 2016 | C5: January | D5: 126.3 | E5: Egg | F5: 128.6 | G5: Food And Beverages
A6: Rural+Urban | B6: 2016 | C6: January | D6: 126.3 | E6: Milk and products | F6: 129.9 | G6: Food And Beverages
A7: Rural+Urban | B7: 2016 | C7: January | D7: 126.3 | E7: Oils and fats | F7: 115.5 | G7: Food And Beverages
A8: Rural+Urban | B8: 2016 | C8: January | D8: 126.3 | E8: Fruits | F8: 125.7 | G8: Food And Beverages
A9: Rural+Urban | B9: 2016 | C9: January | D9: 126.3 | E9: Vegetables | F9: 141.5 | G9: Food And Beverages
A10: Rural+Urban | B10: 2016 | C10: January | D10: 126.3 | E10: Pulses and products | F10: 170.7 | G10: Food And Beverages
A11: Rural+Urban | B11: 2016 | C11: January | D11: 126.3 | E11: Sugar and Confectionery | F11: 97.4 | G11: Food And Beverages
A12: Rural+Urban | B12: 2016 | C12: January | D12: 126.3 | E12: Spices | F12: 132.9 | G12: Food And Beverages
A13: Rural+Urban | B13: 2016 | C13: January | D13: 126.3 | E13: Non-alcoholic beverages | F13: 122.7 | G13: Food And Beverages
A14: Rural+Urban | B14: 2016 | C14: January | D14: 126.3 | E14: Prepared meals, snacks, sweets etc. | F14: 135.3 | G14: Food And Beverages
... A314: Rural+Urban | B314: 2016 | C314: December | D314: 130.4 | E314: Miscellaneous | F314: 123.9 | G314: Miscellaneous
A315: Rural+Urban | B315: 2017 | C315: January | D315: 130.3 | E315: Cereals and products | F315: 132.8 | G315: Food And Beverages | H315: =(D315-D3)/D3*100 -> 3.1670625 | K315: Row Labels | L315: Average of YoY % Increase
A316: Rural+Urban | B316: 2017 | C316: January | D316: 130.3 | E316: Meat and fish | F316: 138.2 | G316: Food And Beverages | H316: =(D316-D4)/D4*100 -> 3.1670625 | K316: 2017 | L316: 3.3273885
A317: Rural+Urban | B317: 2017 | C317: January | D317: 130.3 | E317: Egg | F317: 132.2 | G317: Food And Beverages | H317: =(D317-D5)/D5*100 -> 3.1670625 | K317: 2018 | L317: 3.9676972
A318: Rural+Urban | B318: 2017 | C318: January | D318: 130.3 | E318: Milk and products | F318: 135.4 | G318: Food And Beverages | H318: =(D318-D6)/D6*100 -> 3.1670625 | K318: 2019 | L318: 3.972956
A319: Rural+Urban | B319: 2017 | C319: January | D319: 130.3 | E319: Oils and fats | F319: 119.1 | G319: Food And Beverages | H319: =(D319-D7)/D7*100 -> 3.1670625 | K319: 2020 | L319: 7.4685746
A320: Rural+Urban | B320: 2017 | C320: January | D320: 130.3 | E320: Fruits | F320: 133 | G320: Food And Beverages | H320: =(D320-D8)/D8*100 -> 3.1670625 | K320: 2021 | L320: 5.7203072
A321: Rural+Urban | B321: 2017 | C321: January | D321: 130.3 | E321: Vegetables | F321: 119.4 | G321: Food And Beverages | H321: =(D321-D9)/D9*100 -> 3.1670625 | K321: 2022 | L321: 6.624065
A322: Rural+Urban | B322: 2017 | C322: January | D322: 130.3 | E322: Pulses and products | F322: 159.5 | G322: Food And Beverages | H322: =(D322-D10)/D10*100 -> 3.1670625 | K322: 2023 | L322: 5.5756722
A323: Rural+Urban | B323: 2017 | C323: January | D323: 130.3 | E323: Sugar and Confectionery | F323: 115.6 | G323: Food And Beverages | H323: =(D323-D11)/D11*100 -> 3.1670625 | K323: Grand Total | L323: 5.1613529
A324: Rural+Urban | B324: 2017 | C324: January | D324: 130.3 | E324: Spices | F324: 139.6 | G324: Food And Beverages | H324: =(D324-D12)/D12*100 -> 3.1670625
A325: Rural+Urban | B325: 2017 | C325: January | D325: 130.3 | E325: Non-alcoholic beverages | F325: 126.6 | G325: Food And Beverages | H325: =(D325-D13)/D13*100 -> 3.1670625
A326: Rural+Urban | B326: 2017 | C326: January | D326: 130.3 | E326: Prepared meals, snacks, sweets etc. | F326: 142.8 | G326: Food And Beverages | H326: =(D326-D14)/D14*100 -> 3.1670625
A327: Rural+Urban | B327: 2017 | C327: January | D327: 130.3 | E327: Food and beverages | F327: 133.1 | G327: Food And Beverages | H327: =(D327-D15)/D15*100 -> 3.1670625
A328: Rural+Urban | B328: 2017 | C328: January | D328: 130.3 | E328: Pan, tobacco and intoxicants | F328: 143.8 | G328: Tobacco and Intoxicants | H328: =(D328-D16)/D16*100 -> 3.1670625
A329: Rural+Urban | B329: 2017 | C329: January | D329: 130.3 | E329: Clothing | F329: 136.6 | G329: Clothing and Footwear | H329: =(D329-D17)/D17*100 -> 3.1670625
A330: Rural+Urban | B330: 2017 | C330: January | D330: 130.3 | E330: Footwear | F330: 130.2 | G330: Clothing and Footwear | H330: =(D330-D18)/D18*100 -> 3.1670625
A331: Rural+Urban | B331: 2017 | C331: January | D331: 130.3 | E331: Clothing and footwear | F331: 135.6 | G331: Clothing and Footwear | H331: =(D331-D19)/D19*100 -> 3.1670625
A332: Rural+Urban | B332: 2017 | C332: January | D332: 130.3 | E332: Housing | F332: 129.6 | G332: Housing | H332: =(D332-D20)/D20*100 -> 3.1670625
A333: Rural+Urban | B333: 2017 | C333: January | D333: 130.3 | E333: Fuel and light | F333: 126.8 | G333: Fuel and Light | H333: =(D333-D21)/D21*100 -> 3.1670625
A334: Rural+Urban | B334: 2017 | C334: January | D334: 130.3 | E334: Household goods and services | F334: 129.4 | G334: Household Goods/Services | H334: =(D334-D22)/D22*100 -> 3.1670625
A335: Rural+Urban | B335: 2017 | C335: January | D335: 130.3 | E335: Health | F335: 127.1 | G335: Health | H335: =(D335-D23)/D23*100 -> 3.1670625
... A2238: Rural+Urban | B2238: 2023 | C2238: May | D2238: 179.1 | E2238: Miscellaneous | F2238: 175.7 | G2238: Miscellaneous | H2238: =(D2238-D1926)/D1926*100 -> 4.3098427

Sheet Q3
A1: With India's retail inflation reaching a 3-month high of 5.55% in November 2023, largely due to a sharp rise in food prices. Analyze the following for 12 months ending May'23
A2: Sector | B2: Year | C2: Month | D2: General index | E2: Categories | F2: Value | G2: Broad Categories | H2: Date
A3: Rural | B3: 2022 | C3: June | D3: 173.6 | E3: Cereals and products | F3: 153.8 | G3: Food And Beverages | H3: 44713 | J3: Row Labels | K3: Average of Value | M3: Month | N3: Avg CPI Value | O3: MoM%
A4: Rural | B4: 2022 | C4: June | D4: 173.6 | E4: Meat and fish | F4: 217.2 | G4: Food And Beverages | H4: 44713 | J4: 2022 | K4: 175.60879 | M4: June | N4: 174.3
A5: Rural | B5: 2022 | C5: June | D5: 173.6 | E5: Egg | F5: 169.6 | G5: Food And Beverages | H5: 44713 | J5: June | K5: 174.3 | M5: July | N5: 174.62564 | O5: =(N5-N4)/N4*100 -> 0.1868279
A6: Rural | B6: 2022 | C6: June | D6: 173.6 | E6: Milk and products | F6: 165.4 | G6: Food And Beverages | H6: 44713 | J6: July | K6: 174.62564 | M6: August | N6: 174.83846 | O6: =(N6-N5)/N5*100 -> 0.12187243
A7: Rural | B7: 2022 | C7: June | D7: 173.6 | E7: Oils and fats | F7: 208.1 | G7: Food And Beverages | H7: 44713 | J7: August | K7: 174.83846 | M7: September | N7: 175.77179 | O7: =(N7-N6)/N6*100 -> 0.5338261
A8: Rural | B8: 2022 | C8: June | D8: 173.6 | E8: Fruits | F8: 165.8 | G8: Food And Beverages | H8: 44713 | J8: September | K8: 175.77179 | M8: October | N8: 177.02821 | O8: =(N8-N7)/N7*100 -> 0.71479628
A9: Rural | B9: 2022 | C9: June | D9: 173.6 | E9: Vegetables | F9: 167.3 | G9: Food And Beverages | H9: 44713 | J9: October | K9: 177.02821 | M9: November | N9: 176.89487 | O9: =(N9-N8)/N8*100 -> -0.075317565
A10: Rural | B10: 2022 | C10: June | D10: 173.6 | E10: Pulses and products | F10: 164.6 | G10: Food And Beverages | H10: 44713 | J10: November | K10: 176.89487 | M10: December | N10: 175.80256 | O10: =(N10-N9)/N9*100 -> -0.61748974
A11: Rural | B11: 2022 | C11: June | D11: 173.6 | E11: Sugar and Confectionery | F11: 119.1 | G11: Food And Beverages | H11: 44713 | J11: December | K11: 175.80256 | M11: January | N11: 176.56667 | O11: =(N11-N10)/N10*100 -> 0.43463676
A12: Rural | B12: 2022 | C12: June | D12: 173.6 | E12: Spices | F12: 188.9 | G12: Food And Beverages | H12: 44713 | J12: 2023 | K12: 176.39333 | M12: February | N12: 175.58974 | O12: =(N12-N11)/N11*100 -> -0.55328851
A13: Rural | B13: 2022 | C13: June | D13: 173.6 | E13: Non-alcoholic beverages | F13: 174.2 | G13: Food And Beverages | H13: 44713 | J13: January | K13: 176.56667 | M13: March | N13: 175.6 | O13: =(N13-N12)/N12*100 -> 0.0058411215
A14: Rural | B14: 2022 | C14: June | D14: 173.6 | E14: Prepared meals, snacks, sweets etc. | F14: 181.9 | G14: Food And Beverages | H14: 44713 | J14: February | K14: 175.58974 | M14: April | N14: 176.44872 | O14: =(N14-N13)/N13*100 -> 0.48332457
A15: Rural | B15: 2022 | C15: June | D15: 173.6 | E15: Food and beverages | F15: 172.4 | G15: Food And Beverages | H15: 44713 | J15: March | K15: 175.6 | M15: May | N15: 177.76154 | O15: =(N15-N14)/N14*100 -> 0.74402383
A16: Urban | B16: 2022 | C16: June | D16: 171.4 | E16: Cereals and products | F16: 157.5 | G16: Food And Beverages | H16: 44713 | J16: April | K16: 176.44872
A17: Urban | B17: 2022 | C17: June | D17: 171.4 | E17: Meat and fish | F17: 223.4 | G17: Food And Beverages | H17: 44713 | J17: May | K17: 177.76154
A18: Urban | B18: 2022 | C18: June | D18: 171.4 | E18: Egg | F18: 172.8 | G18: Food And Beverages | H18: 44713 | J18: Grand Total | K18: 175.93568
A19: Urban | B19: 2022 | C19: June | D19: 171.4 | E19: Milk and products | F19: 166.4 | G19: Food And Beverages | H19: 44713
A20: Urban | B20: 2022 | C20: June | D20: 171.4 | E20: Oils and fats | F20: 188.6 | G20: Food And Beverages | H20: 44713
A21: Urban | B21: 2022 | C21: June | D21: 171.4 | E21: Fruits | F21: 174.1 | G21: Food And Beverages | H21: 44713
A22: Urban | B22: 2022 | C22: June | D22: 171.4 | E22: Vegetables | F22: 211.5 | G22: Food And Beverages | H22: 44713
A23: Urban | B23: 2022 | C23: June | D23: 171.4 | E23: Pulses and products | F23: 163.6 | G23: Food And Beverages | H23: 44713
A24: Urban | B24: 2022 | C24: June | D24: 171.4 | E24: Sugar and Confectionery | F24: 121.4 | G24: Food And Beverages | H24: 44713
A25: Urban | B25: 2022 | C25: June | D25: 171.4 | E25: Spices | F25: 183.5 | G25: Food And Beverages | H25: 44713
A26: Urban | B26: 2022 | C26: June | D26: 171.4 | E26: Non-alcoholic beverages | F26: 159.1 | G26: Food And Beverages | H26: 44713
A27: Urban | B27: 2022 | C27: June | D27: 171.4 | E27: Prepared meals, snacks, sweets etc. | F27: 186.3 | G27: Food And Beverages | H27: 44713
A28: Urban | B28: 2022 | C28: June | D28: 171.4 | E28: Food and beverages | F28: 179.3 | G28: Food And Beverages | H28: 44713
A29: Rural+Urban | B29: 2022 | C29: June | D29: 172.6 | E29: Cereals and products | F29: 155 | G29: Food And Beverages | H29: 44713
A30: Rural+Urban | B30: 2022 | C30: June | D30: 172.6 | E30: Meat and fish | F30: 219.4 | G30: Food And Beverages | H30: 44713
... A36: Rural+Urban | B36: 2022 | C36: June | D36: 172.6 | E36: Pulses and products | F36: 164.3 | G36: Food And Beverages | H36: 44713
A37: Rural+Urban | B37: 2022 | C37: June | D37: 172.6 | E37: Sugar and Confectionery | F37: 119.9 | G37: Food And Beverages | H37: 44713 | N37: Row Labels | O37: Max of Value | P37: Min of Value | Q37: Absolute Change
A38: Rural+Urban | B38: 2022 | C38: June | D38: 172.6 | E38: Spices | F38: 187.1 | G38: Food And Beverages | H38: 44713 | N38: Vegetables | O38: 228.6 | P38: 140.9 | Q38: =O38-P38 -> 87.7
A39: Rural+Urban | B39: 2022 | C39: June | D39: 172.6 | E39: Non-alcoholic beverages | F39: 167.9 | G39: Food And Beverages | H39: 44713 | N39: Oils and fats | O39: 208.1 | P39: 164.4 | Q39: =O39-P39 -> 43.7
A40: Rural+Urban | B40: 2022 | C40: June | D40: 172.6 | E40: Prepared meals, snacks, sweets etc. | F40: 183.9 | G40: Food And Beverages | H40: 44713 | N40: Spices | O40: 221 | P40: 183.5 | Q40: =O40-P40 -> 37.5
A41: Rural+Urban | B41: 2022 | C41: June | D41: 172.6 | E41: Food and beverages | F41: 174.9 | G41: Food And Beverages | H41: 44713 | N41: Egg | O41: 197 | P41: 167.9 | Q41: =O41-P41 -> 29.1
A42: Rural | B42: 2022 | C42: July | D42: 174.3 | E42: Cereals and products | F42: 155.2 | G42: Food And Beverages | H42: 44743 | N42: Fruits | O42: 179.5 | P42: 156.3 | Q42: =O42-P42 -> 23.2
A43: Rural | B43: 2022 | C43: July | D43: 174.3 | E43: Meat and fish | F43: 210.8 | G43: Food And Beverages | H43: 44743 | N43: Cereals and products | O43: 174.8 | P43: 153.8 | Q43: =O43-P43 -> 21
A44: Rural | B44: 2022 | C44: July | D44: 174.3 | E44: Egg | F44: 174.3 | G44: Food And Beverages | H44: 44743 | N44: Non-alcoholic beverages | O44: 178.7 | P44: 159.1 | Q44: =O44-P44 -> 19.6
A45: Rural | B45: 2022 | C45: July | D45: 174.3 | E45: Milk and products | F45: 166.3 | G45: Food And Beverages | H45: 44743 | N45: Meat and fish | O45: 223.4 | P45: 204.1 | Q45: =O45-P45 -> 19.3
...

Sheet Q4
A1: Sector | B1: Year | C1: Month | D1: General index | E1: Categories | F1: Value | G1: Broad Categories | H1: Date | I1: Period
A2: Rural | B2: 2013 | C2: January | D2: 105.1 | E2: Cereals and products | F2: 107.5 | G2: Food And Beverages | H2: =DATE(B2,MONTH(DATEVALUE(C2 & " 1")),1) -> 41275 | I2: =IF(H2<DATE(2023,3,1),"Pre-Covid","Post-Covid") -> Pre-Covid
A3: Rural | B3: 2013 | C3: January | D3: 105.1 | E3: Meat and fish | F3: 106.3 | G3: Food And Beverages | H3: =DATE(B3,MONTH(DATEVALUE(C3 & " 1")),1) -> 41275 | I3: =IF(H3<DATE(2023,3,1),"Pre-Covid","Post-Covid") -> Pre-Covid | K3: Row Labels | L3: Average of Value
A4: Rural | B4: 2013 | C4: January | D4: 105.1 | E4: Egg | F4: 108.1 | G4: Food And Beverages | H4: =DATE(B4,MONTH(DATEVALUE(C4 & " 1")),1) -> 41275 | I4: =IF(H4<DATE(2023,3,1),"Pre-Covid","Post-Covid") -> Pre-Covid | K4: Post-Covid | L4: 176.6915
A5: Rural | B5: 2013 | C5: January | D5: 105.1 | E5: Milk and products | F5: 104.9 | G5: Food And Beverages | H5: =DATE(B5,MONTH(DATEVALUE(C5 & " 1")),1) -> 41275 | I5: =IF(H5<DATE(2023,3,1),"Pre-Covid","Post-Covid") -> Pre-Covid | K5: Pre-Covid | L5: 138.33218
A6: Rural | B6: 2013 | C6: January | D6: 105.1 | E6: Oils and fats | F6: 106.1 | G6: Food And Beverages | H6: =DATE(B6,MONTH(DATEVALUE(C6 & " 1")),1) -> 41275 | I6: =IF(H6<DATE(2023,3,1),"Pre-Covid","Post-Covid") -> Pre-Covid | K6: Grand Total | L6: 139.27544
A7: Rural | B7: 2013 | C7: January | D7: 105.1 | E7: Fruits | F7: 103.9 | G7: Food And Beverages | H7: =DATE(B7,MONTH(DATEVALUE(C7 & " 1")),1) -> 41275 | I7: =IF(H7<DATE(2023,3,1),"Pre-Covid","Post-Covid") -> Pre-Covid
A8: Rural | B8: 2013 | C8: January | D8: 105.1 | E8: Vegetables | F8: 101.9 | G8: Food And Beverages | H8: =DATE(B8,MONTH(DATEVALUE(C8 & " 1")),1) -> 41275 | I8: =IF(H8<DATE(2023,3,1),"Pre-Covid","Post-Covid") -> Pre-Covid
A9: Rural | B9: 2013 | C9: January | D9: 105.1 | E9: Pulses and products | F9: 106.1 | G9: Food And Beverages | H9: =DATE(B9,MONTH(DATEVALUE(C9 & " 1")),1) -> 41275 | I9: =IF(H9<DATE(2023,3,1),"Pre-Covid","Post-Covid") -> Pre-Covid
A10: Rural | B10: 2013 | C10: January | D10: 105.1 | E10: Sugar and Confectionery | F10: 106.8 | G10: Food And Beverages | H10: =DATE(B10,MONTH(DATEVALUE(C10 & " 1")),1) -> 41275 | I10: =IF(H10<DATE(2023,3,1),"Pre-Covid","Post-Covid") -> Pre-Covid
A11: Rural | B11: 2013 | C11: January | D11: 105.1 | E11: Spices | F11: 103.1 | G11: Food And Beverages | H11: =DATE(B11,MONTH(DATEVALUE(C11 & " 1")),1) -> 41275 | I11: =IF(H11<DATE(2023,3,1),"Pre-Covid","Post-Covid") -> Pre-Covid
A12: Rural | B12: 2013 | C12: January | D12: 105.1 | E12: Non-alcoholic beverages | F12: 104.8 | G12: Food And Beverages | H12: =DATE(B12,MONTH(DATEVALUE(C12 & " 1")),1) -> 41275 | I12: =IF(H12<DATE(2023,3,1),"Pre-Covid","Post-Covid") -> Pre-Covid
A13: Rural | B13: 2013 | C13: January | D13: 105.1 | E13: Prepared meals, snacks, sweets etc. | F13: 106.7 | G13: Food And Beverages | H13: =DATE(B13,MONTH(DATEVALUE(C13 & " 1")),1) -> 41275 | I13: =IF(H13<DATE(2023,3,1),"Pre-Covid","Post-Covid") -> Pre-Covid
A14: Rural | B14: 2013 | C14: January | D14: 105.1 | E14: Food and beverages | F14: 105.5 | G14: Food And Beverages | H14: =DATE(B14,MONTH(DATEVALUE(C14 & " 1")),1) -> 41275 | I14: =IF(H14<DATE(2023,3,1),"Pre-Covid","Post-Covid") -> Pre-Covid
A15: Rural | B15: 2013 | C15: January | D15: 105.1 | E15: Fuel and light | F15: 105.5 | G15: Fuel and Light | H15: =DATE(B15,MONTH(DATEVALUE(C15 & " 1")),1) -> 41275 | I15: =IF(H15<DATE(2023,3,1),"Pre-Covid","Post-Covid") -> Pre-Covid
A16: Rural | B16: 2013 | C16: January | D16: 105.1 | E16: Health | F16: 104 | G16: Health | H16: =DATE(B16,MONTH(DATEVALUE(C16 & " 1")),1) -> 41275 | I16: =IF(H16<DATE(2023,3,1),"Pre-Covid","Post-Covid") -> Pre-Covid
A17: Rural | B17: 2013 | C17: January | D17: 105.1 | E17: Transport and communication | F17: 103.3 | G17: Transport and Communication | H17: =DATE(B17,MONTH(DATEVALUE(C17 & " 1")),1) -> 41275 | I17: =IF(H17<DATE(2023,3,1),"Pre-Covid","Post-Covid") -> Pre-Covid
A18: Rural | B18: 2013 | C18: January | D18: 105.1 | E18: Education | F18: 103.8 | G18: Education | H18: =DATE(B18,MONTH(DATEVALUE(C18 & " 1")),1) -> 41275 | I18: =IF(H18<DATE(2023,3,1),"Pre-Covid","Post-Covid") -> Pre-Covid
... A25: Urban | B25: 2013 | C25: January | D25: 104 | E25: Vegetables | F25: 102.9 | G25: Food And Beverages | H25: =DATE(B25,MONTH(DATEVALUE(C25 & " 1")),1) -> 41275 | I25: =IF(H25<DATE(2023,3,1),"Pre-Covid","Post-Covid") -> Pre-Covid
A26: Urban | B26: 2013 | C26: January | D26: 104 | E26: Pulses and products | F26: 105.8 | G26: Food And Beverages | H26: =DATE(B26,MONTH(DATEVALUE(C26 & " 1")),1) -> 41275 | I26: =IF(H26<DATE(2023,3,1),"Pre-Covid","Post-Covid") -> Pre-Covid | K26: Row Labels | L26: Average of General index
A27: Urban | B27: 2013 | C27: January | D27: 104 | E27: Sugar and Confectionery | F27: 105.1 | G27: Food And Beverages | H27: =DATE(B27,MONTH(DATEVALUE(C27 & " 1")),1) -> 41275 | I27: =IF(H27<DATE(2023,3,1),"Pre-Covid","Post-Covid") -> Pre-Covid | K27: Post-Covid | L27: 178.1
A28: Urban | B28: 2013 | C28: January | D28: 104 | E28: Spices | F28: 101.8 | G28: Food And Beverages | H28: =DATE(B28,MONTH(DATEVALUE(C28 & " 1")),1) -> 41275 | I28: =IF(H28<DATE(2023,3,1),"Pre-Covid","Post-Covid") -> Pre-Covid | K28: Pre-Covid | L28: 138.593
A29: Urban | B29: 2013 | C29: January | D29: 104 | E29: Non-alcoholic beverages | F29: 105.1 | G29: Food And Beverages | H29: =DATE(B29,MONTH(DATEVALUE(C29 & " 1")),1) -> 41275 | I29: =IF(H29<DATE(2023,3,1),"Pre-Covid","Post-Covid") -> Pre-Covid | K29: Grand Total | L29: 139.56448
A30: Urban | B30: 2013 | C30: January | D30: 104 | E30: Prepared meals, snacks, sweets etc. | F30: 107.9 | G30: Food And Beverages | H30: =DATE(B30,MONTH(DATEVALUE(C30 & " 1")),1) -> 41275 | I30: =IF(H30<DATE(2023,3,1),"Pre-Covid","Post-Covid") -> Pre-Covid
A31: Urban | B31: 2013 | C31: January | D31: 104 | E31: Food and beverages | F31: 105.9 | G31: Food And Beverages | H31: =DATE(B31,MONTH(DATEVALUE(C31 & " 1")),1) -> 41275 | I31: =IF(H31<DATE(2023,3,1),"Pre-Covid","Post-Covid") -> Pre-Covid
A32: Urban | B32: 2013 | C32: January | D32: 104 | E32: Fuel and light | F32: 105.4 | G32: Fuel and Light | H32: =DATE(B32,MONTH(DATEVALUE(C32 & " 1")),1) -> 41275 | I32: =IF(H32<DATE(2023,3,1),"Pre-Covid","Post-Covid") -> Pre-Covid
A33: Urban | B33: 2013 | C33: January | D33: 104 | E33: Health | F33: 104.1 | G33: Health | H33: =DATE(B33,MONTH(DATEVALUE(C33 & " 1")),1) -> 41275 | I33: =IF(H33<DATE(2023,3,1),"Pre-Covid","Post-Covid") -> Pre-Covid
A34: Urban | B34: 2013 | C34: January | D34: 104 | E34: Transport and communication | F34: 103.2 | G34: Transport and Communication | H34: =DATE(B34,MONTH(DATEVALUE(C34 & " 1")),1) -> 41275 | I34: =IF(H34<DATE(2023,3,1),"Pre-Covid","Post-Covid") -> Pre-Covid
A35: Urban | B35: 2013 | C35: January | D35: 104 | E35: Education | F35: 103.5 | G35: Education | H35: =DATE(B35,MONTH(DATEVALUE(C35 & " 1")),1) -> 41275 | I35: =IF(H35<DATE(2023,3,1),"Pre-Covid","Post-Covid") -> Pre-Covid
A36: Rural+Urban | B36: 2013 | C36: January | D36: 104.6 | E36: Cereals and products | F36: 108.4 | G36: Food And Beverages | H36: =DATE(B36,MONTH(DATEVALUE(C36 & " 1")),1) -> 41275 | I36: =IF(H36<DATE(2023,3,1),"Pre-Covid","Post-Covid") -> Pre-Covid
A37: Rural+Urban | B37: 2013 | C37: January | D37: 104.6 | E37: Meat and fish | F37: 107.3 | G37: Food And Beverages | H37: =DATE(B37,MONTH(DATEVALUE(C37 & " 1")),1) -> 41275 | I37: =IF(H37<DATE(2023,3,1),"Pre-Covid","Post-Covid") -> Pre-Covid
A38: Rural+Urban | B38: 2013 | C38: January | D38: 104.6 | E38: Egg | F38: 110 | G38: Food And Beverages | H38: =DATE(B38,MONTH(DATEVALUE(C38 & " 1")),1) -> 41275 | I38: =IF(H38<DATE(2023,3,1),"Pre-Covid","Post-Covid") -> Pre-Covid
A39: Rural+Urban | B39: 2013 | C39: January | D39: 104.6 | E39: Milk and products | F39: 104.4 | G39: Food And Beverages | H39: =DATE(B39,MONTH(DATEVALUE(C39 & " 1")),1) -> 41275 | I39: =IF(H39<DATE(2023,3,1),"Pre-Covid","Post-Covid") -> Pre-Covid
A40: Rural+Urban | B40: 2013 | C40: January | D40: 104.6 | E40: Oils and fats | F40: 105.1 | G40: Food And Beverages | H40: =DATE(B40,MONTH(DATEVALUE(C40 & " 1")),1) -> 41275 | I40: =IF(H40<DATE(2023,3,1),"Pre-Covid","Post-Covid") -> Pre-Covid
A41: Rural+Urban | B41: 2013 | C41: January | D41: 104.6 | E41: Fruits | F41: 103.2 | G41: Food And Beverages | H41: =DATE(B41,MONTH(DATEVALUE(C41 & " 1")),1) -> 41275 | I41: =IF(H41<DATE(2023,3,1),"Pre-Covid","Post-Covid") -> Pre-Covid
... A6223: Rural+Urban | B6223: 2023 | C6223: May | D6223: 179.1 | E6223: Education | F6223: 177.1 | G6223: Education | H6223: =DATE(B6223,MONTH(DATEVALUE(C6223 & " 1")),1) -> 45047 | I6223: =IF(H6223<DATE(2023,3,1),"Pre-Covid","Post-Covid") -> Post-Covid

Sheet Q5 Helper
A1: Sector | B1: Year | C1: Month | D1: General index | E1: Categories | F1: Value | G1: Broad Categories | H1: Date
A2: Rural | B2: 2021 | C2: January | D2: 158.5 | E2: Cereals and products | F2: 143.4 | G2: Food And Beverages | H2: =DATE(B2,MONTH(DATEVALUE(C2&" 1")),1) -> 44197 | K2: Average of Value | L2: Column Labels
A3: Rural | B3: 2021 | C3: January | D3: 158.5 | E3: Meat and fish | F3: 187.5 | G3: Food And Beverages | H3: =DATE(B3,MONTH(DATEVALUE(C3&" 1")),1) -> 44197 | K3: Row Labels | L3: Clothing and Footwear | M3: Education | N3: Food And Beverages | O3: Fuel and Light | P3: Health | Q3: Household Goods/Services | R3: Housing | S3: Miscellaneous | T3: Personal Care/Effects | U3: Recreation and Amusement | V3: Tobacco and Intoxicants | W3: Transport and Communication | X3: Grand Total
A4: Rural | B4: 2021 | C4: January | D4: 158.5 | E4: Egg | F4: 173.4 | G4: Food And Beverages | H4: =DATE(B4,MONTH(DATEVALUE(C4&" 1")),1) -> 44197 | K4: 2021 | L4: 157.7713 | M4: 162.53611 | N4: 163.33739 | O4: 158.70833 | P4: 165.13333 | Q4: 155 | R4: 161.48333 | S4: 157.50833 | T4: 158.73889 | U4: 155.94444 | V4: 191.67778 | W4: 150.7 | X4: 162.08972
A5: Rural | B5: 2021 | C5: January | D5: 158.5 | E5: Milk and products | F5: 154 | G5: Food And Beverages | H5: =DATE(B5,MONTH(DATEVALUE(C5&" 1")),1) -> 44197 | K5: Jan | L5: 151.38889 | M5: 159.6 | N5: 159.97949 | O5: 147.23333 | P5: 158.63333 | Q5: 149.86667 | R5: 157.7 | S5: 151.8 | T5: 156.9 | U5: 150.03333 | V5: 187.63333 | W5: 142.1 | X5: 157.51299
A6: Rural | B6: 2021 | C6: January | D6: 158.5 | E6: Oils and fats | F6: 154.8 | G6: Food And Beverages | H6: =DATE(B6,MONTH(DATEVALUE(C6&" 1")),1) -> 44197 | K6: Feb | L6: 152.88889 | M6: 159.9 | N6: 157.19487 | O6: 151.96667 | P6: 160.63333 | Q6: 150.73333 | R6: 159.8 | S6: 153.3 | T6: 155.9 | U6: 151.93333 | V6: 189.36667 | W6: 145.26667 | X6: 156.92468
A7: Rural | B7: 2021 | C7: January | D7: 158.5 | E7: Fruits | F7: 147 | G7: Food And Beverages | H7: =DATE(B7,MONTH(DATEVALUE(C7&" 1")),1) -> 44197 | K7: Mar | L7: 153.48889 | M7: 160.53333 | N7: 157.16923 | O7: 155.43333 | P7: 161.06667 | Q7: 151.06667 | R7: 159.9 | S7: 153.7 | T7: 153.93333 | U7: 153 | V7: 189.23333 | W7: 146.4 | X7: 157.19351
A8: Rural | B8: 2021 | C8: January | D8: 158.5 | E8: Vegetables | F8: 187.8 | G8: Food And Beverages | H8: =DATE(B8,MONTH(DATEVALUE(C8&" 1")),1) -> 44197 | K8: Apr | L8: 154.32222 | M8: 160.66667 | N8: 159.05641 | O8: 155.5 | P8: 161.7 | Q8: 151.63333 | R8: 161.4 | S8: 154.3 | T8: 155.53333 | U8: 153.63333 | V8: 190 | W8: 146.8 | X8: 158.4961
A9: Rural | B9: 2021 | C9: January | D9: 158.5 | E9: Pulses and products | F9: 159.5 | G9: Food And Beverages | H9: =DATE(B9,MONTH(DATEVALUE(C9&" 1")),1) -> 44197 | K9: May | L9: 157.27778 | M9: 161.8 | N9: 162.19744 | O9: 158.86667 | P9: 165.1 | Q9: 154.53333 | R9: 161.6 | S9: 156.73333 | T9: 158.46667 | U9: 156.13333 | V9: 193.23333 | W9: 149.03333 | X9: 161.37792
A10: Rural | B10: 2021 | C10: January | D10: 158.5 | E10: Sugar and Confectionery | F10: 113.8 | G10: Food And Beverages | H10: =DATE(B10,MONTH(DATEVALUE(C10&" 1")),1) -> 44197 | K10: Jun | L10: 157.45556 | M10: 162.2 | N10: 164.37692 | O10: 159.33333 | P10: 165.6 | Q10: 154.6 | R10: 160.5 | S10: 157.5 | T10: 158.73333 | U10: 155.33333 | V10: 191.83333 | W10: 150.8 | X10: 162.55325
A11: Rural | B11: 2021 | C11: January | D11: 158.5 | E11: Spices | F11: 164.5 | G11: Food And Beverages | H11: =DATE(B11,MONTH(DATEVALUE(C11&" 1")),1) -> 44197 | K11: Jul | L11: 158.33333 | M11: 163.56667 | N11: 165.41538 | O11: 160.3 | P11: 166.3 | Q11: 155.6 | R11: 161.5 | S11: 158.93333 | T11: 160.03333 | U11: 155.73333 | V11: 192.13333 | W11: 153.23333 | X11: 163.59351
A12: Rural | B12: 2021 | C12: January | D12: 158.5 | E12: Non-alcoholic beverages | F12: 156.1 | G12: Food And Beverages | H12: =DATE(B12,MONTH(DATEVALUE(C12&" 1")),1) -> 44197 | K12: Aug | L12: 159.95556 | M12: 163.9 | N12: 164.88974 | O12: 162.13333 | P12: 167.43333 | Q12: 157.2 | R12: 162.1 | S12: 159.76667 | T12: 159.96667 | U12: 157.46667 | V12: 192.93333 | W12: 154.03333 | X12: 163.88312
A13: Rural | B13: 2021 | C13: January | D13: 158.5 | E13: Prepared meals, snacks, sweets etc. | F13: 164.3 | G13: Food And Beverages | H13: =DATE(B13,MONTH(DATEVALUE(C13&" 1")),1) -> 44197 | K13: Sep | L13: 160.26667 | M13: 164.16667 | N13: 164.96154 | O13: 162.36667 | P13: 167.7 | Q13: 157.36667 | R13: 162.1 | S13: 159.93333 | T13: 159.93333 | U13: 158.1 | V13: 193.03333 | W13: 154.1 | X13: 164.02857
A14: Rural | B14: 2021 | C14: January | D14: 158.5 | E14: Food and beverages | F14: 159.6 | G14: Food And Beverages | H14: =DATE(B14,MONTH(DATEVALUE(C14&" 1")),1) -> 44197 | K14: Oct | L14: 161.31111 | M14: 164.4 | N14: 167.64359 | O14: 163.96667 | P14: 168.36667 | Q14: 158.23333 | R14: 163.6 | S14: 160.9 | T14: 160.73333 | U14: 158.96667 | V14: 193.63333 | W14: 155.8 | X14: 165.87143
A15: Rural | B15: 2021 | C15: January | D15: 158.5 | E15: Pan, tobacco and intoxicants | F15: 184.6 | G15: Tobacco and Intoxicants | H15: =DATE(B15,MONTH(DATEVALUE(C15&" 1")),1) -> 44197 | K15: Nov | L15: 162.65556 | M15: 164.8 | N15: 169.07692 | O15: 163.6 | P15: 169.16667 | Q15: 159.13333 | R15: 164.2 | S15: 161.3 | T15: 162.13333 | U15: 160.1 | V15: 193.76667 | W15: 154.96667 | X15: 166.92468
... A18: Rural | B18: 2021 | C18: January | D18: 158.5 | E18: Clothing and footwear | F18: 156.8 | G18: Clothing and Footwear | H18: =DATE(B18,MONTH(DATEVALUE(C18&" 1")),1) -> 44197 | K18: Jan | L18: 165.52222 | M18: 165.2 | N18: 166.76667 | O18: 163.86667 | P18: 170.73333 | Q18: 160.93333 | R18: 164.5 | S18: 162.63333 | T18: 163 | U18: 161.5 | V18: 193.1 | W18: 156.66667 | X18: 166.43506
A19: Rural | B19: 2021 | C19: January | D19: 158.5 | E19: Housing | G19: Housing | H19: =DATE(B19,MONTH(DATEVALUE(C19&" 1")),1) -> 44197 | K19: Feb | L19: 166.78889 | M19: 165.9 | N19: 166.54103 | O19: 165.36667 | P19: 171.56667 | Q19: 161.63333 | R19: 165.5 | S19: 163.4 | T19: 164.36667 | U19: 162.36667 | V19: 193.6 | W19: 157.06667 | X19: 166.79221
A20: Rural | B20: 2021 | C20: January | D20: 158.5 | E20: Fuel and light | F20: 150.9 | G20: Fuel and Light | H20: =DATE(B20,MONTH(DATEVALUE(C20&" 1")),1) -> 44197 | K20: Mar | L20: 168.45556 | M20: 166.43333 | N20: 168.19487 | O20: 166.86667 | P20: 172.4 | Q20: 162.63333 | R20: 165.3 | S20: 164.5 | T20: 167.13333 | U20: 163.56667 | V20: 194.5 | W20: 158.03333 | X20: 168.24026
A21: Rural | B21: 2021 | C21: January | D21: 158.5 | E21: Household goods and services | F21: 153.9 | G21: Household Goods/Services | H21: =DATE(B21,MONTH(DATEVALUE(C21&" 1")),1) -> 44197 | K21: Apr | L21: 170.23333 | M21: 167.26667 | N21: 170.54615 | O21: 172 | P21: 173.33333 | Q21: 163.83333 | R21: 167 | S21: 166.7 | T21: 168.73333 | U21: 164.6 | V21: 194.6 | W21: 162.7 | X21: 170.37273
A22: Rural | B22: 2021 | C22: January | D22: 158.5 | E22: Health | F22: 162.5 | G22: Health | H22: =DATE(B22,MONTH(DATEVALUE(C22&" 1")),1) -> 44197 | K22: May | L22: 171.97778 | M22: 168.3 | N22: 172.51026 | O22: 174.46667 | P22: 174.2 | Q22: 165.06667 | R22: 167.5 | S22: 167.4 | T22: 168.36667 | U22: 165.3 | V22: 194.83333 | W22: 163.16667 | X22: 171.87013
A23: Rural | B23: 2021 | C23: January | D23: 158.5 | E23: Transport and communication | F23: 147.5 | G23: Transport and Communication | H23: =DATE(B23,MONTH(DATEVALUE(C23&" 1")),1) -> 44197 | K23: Jun | L23: 173.46667 | M23: 169.36667 | N23: 174.3 | O23: 175.86667 | P23: 174.83333 | Q23: 166.26667 | R23: 166.8 | S23: 167.43333 | T23: 169.36667 | U23: 165.96667 | V23: 195.16667 | W23: 161.26667 | X23: 173.10519
A24: Rural | B24: 2021 | C24: January | D24: 158.5 | E24: Recreation and amusement | F24: 155.1 | G24: Recreation and Amusement | H24: =DATE(B24,MONTH(DATEVALUE(C24&" 1")),1) -> 44197 | K24: Jul | L24: 174.76667 | M24: 171.73333 | N24: 174.62564 | O24: 179.56667 | P24: 175.53333 | Q24: 167.26667 | R24: 167.8 | S24: 168.3 | T24: 169.73333 | U24: 166.5 | V24: 195.46667 | W24: 161.76667 | X24: 173.85065
A25: Rural | B25: 2021 | C25: January | D25: 158.5 | E25: Education | F25: 163.5 | G25: Education | H25: =DATE(B25,MONTH(DATEVALUE(C25&" 1")),1) -> 44197 | K25: Aug | L25: 175.98889 | M25: 172.63333 | N25: 174.83846 | O25: 178.76667 | P25: 176.26667 | Q25: 168.33333 | R25: 169 | S25: 169.03333 | T25: 171.23333 | U25: 167.1 | V25: 195.8 | W25: 162.06667 | X25: 174.34156
A26: Rural | B26: 2021 | C26: January | D26: 158.5 | E26: Personal care and effects | F26: 156.2 | G26: Personal Care/Effects | H26: =DATE(B26,MONTH(DATEVALUE(C26&" 1")),1) -> 44197 | K26: Sep | L26: 177.47778 | M26: 173.4 | N26: 175.77179 | O26: 179.46667 | P26: 177.26667 | Q26: 169.36667 | R26: 169.5 | S26: 169.63333 | T26: 170.93333 | U26: 167.8 | V26: 196.7 | W26: 162.46667 | X26: 175.22727
A27: Rural | B27: 2021 | C27: January | D27: 158.5 | E27: Miscellaneous | F27: 155.9 | G27: Miscellaneous | H27: =DATE(B27,MONTH(DATEVALUE(C27&" 1")),1) -> 44197 | K27: Oct | L27: 178.47778 | M27: 173.7 | N27: 177.02821 | O27: 180.43333 | P27: 178.2 | Q27: 170.26667 | R27: 171.2 | S27: 170.4 | T27: 172.13333 | U27: 168.36667 | V27: 197.1 | W27: 163.03333 | X27: 176.28182
A28: Urban | B28: 2021 | C28: January | D28: 156 | E28: Cereals and products | F28: 148 | G28: Food And Beverages | H28: =DATE(B28,MONTH(DATEVALUE(C28&" 1")),1) -> 44197 | K28: Nov | L28: 179.51111 | M28: 174.03333 | N28: 176.89487 | O28: 181.16667 | P28: 179.3 | Q28: 171.26667 | R28: 171.8 | S28: 171.03333 | T28: 173.6 | U28: 168.66667 | V28: 197.66667 | W28: 163.13333 | X28: 176.59351
A29: Urban | B29: 2021 | C29: January | D29: 156 | E29: Meat and fish | F29: 194.8 | G29: Food And Beverages | H29: =DATE(B29,MONTH(DATEVALUE(C29&" 1")),1) -> 44197 | K29: Dec | L29: 180.41111 | M29: 174.4 | N29: 175.80256 | O29: 181.8 | P29: 180.6 | Q29: 171.93333 | R29: 170.7 | S29: 171.9 | T29: 175.83333 | U29: 169.06667 | V29: 198.1 | W29: 163.53333 | X29: 176.4013
A30: Urban | B30: 2021 | C30: January | D30: 156 | E30: Egg | F30: 178.4 | G30: Food And Beverages | H30: =DATE(B30,MONTH(DATEVALUE(C30&" 1")),1) -> 44197 | K30: Grand Total | L30: 165.68056 | M30: 166.36667 | N30: 168.07788 | O30: 166.83889 | P30: 170.24306 | Q30: 160.78333 | R30: 164.76667 | S30: 162.60278 | T30: 164.1375 | U30: 160.92222 | V30: 193.61528 | W30: 155.97083 | X30: 167.27451
A31: Urban | B31: 2021 | C31: January | D31: 156 | E31: Milk and products | F31: 154.4 | G31: Food And Beverages | H31: =DATE(B31,MONTH(DATEVALUE(C31&" 1")),1) -> 44197
A32: Urban | B32: 2021 | C32: January | D32: 156 | E32: Oils and fats | F32: 144.1 | G32: Food And Beverages | H32: =DATE(B32,MONTH(DATEVALUE(C32&" 1")),1) -> 44197
A33: Urban | B33: 2021 | C33: January | D33: 156 | E33: Fruits | F33: 152.6 | G33: Food And Beverages | H33: =DATE(B33,MONTH(DATEVALUE(C33&" 1")),1) -> 44197
A34: Urban | B34: 2021 | C34: January | D34: 156 | E34: Vegetables | F34: 206.8 | G34: Food And Beverages | H34: =DATE(B34,MONTH(DATEVALUE(C34&" 1")),1) -> 44197
A35: Urban | B35: 2021 | C35: January | D35: 156 | E35: Pulses and products | F35: 162.1 | G35: Food And Beverages | H35: =DATE(B35,MONTH(DATEVALUE(C35&" 1")),1) -> 44197
A36: Urban | B36: 2021 | C36: January | D36: 156 | E36: Sugar and Confectionery | F36: 116.3 | G36: Food And Beverages | H36: =DATE(B36,MONTH(DATEVALUE(C36&" 1")),1) -> 44197
A37: Urban | B37: 2021 | C37: January | D37: 156 | E37: Spices | F37: 163 | G37: Food And Beverages | H37: =DATE(B37,MONTH(DATEVALUE(C37&" 1")),1) -> 44197
A38: Urban | B38: 2021 | C38: January | D38: 156 | E38: Non-alcoholic beverages | F38: 145.9 | G38: Food And Beverages | H38: =DATE(B38,MONTH(DATEVALUE(C38&" 1")),1) -> 44197
A39: Urban | B39: 2021 | C39: January | D39: 156 | E39: Prepared meals, snacks, sweets etc. | F39: 167.2 | G39: Food And Beverages | H39: =DATE(B39,MONTH(DATEVALUE(C39&" 1")),1) -> 44197
A40: Urban | B40: 2021 | C40: January | D40: 156 | E40: Food and beverages | F40: 163.4 | G40: Food And Beverages | H40: =DATE(B40,MONTH(DATEVALUE(C40&" 1")),1) -> 44197
A41: Urban | B41: 2021 | C41: January | D41: 156 | E41: Pan, tobacco and intoxicants | F41: 191.8 | G41: Tobacco and Intoxicants | H41: =DATE(B41,MONTH(DATEVALUE(C41&" 1")),1) -> 44197
A42: Urban | B42: 2021 | C42: January | D42: 156 | E42: Clothing | F42: 152.5 | G42: Clothing and Footwear | H42: =DATE(B42,MONTH(DATEVALUE(C42&" 1")),1) -> 44197
...

Sheet Q5
A1: Year | B1: Month | C1: Value | D1: Date | E1: MoM % Change | G1: Year | H1: Month | I1: Clothing and Footwear | J1: Clothing and Footware MoM% | K1: Education | L1: Education MoM% | M1: Food And Beverages | N1: Food And Beverages MoM% | O1: Fuel and Light | P1: Fuel and Light MoM% | Q1: Health | R1: Health MoM% | S1: Household Goods/Services | T1: Household Goods/Services MoM% | U1: Housing | V1: Housing MoM% | W1: Miscellaneous | X1: Miscellaneous MoM% | Y1: Personal Care/Effects | Z1: Personal Care/Effects MoM% | AA1: Recreation and Amusement | AB1: Recreation and Amusement MoM% | AC1: Tobacco and Intoxicants | AD1: Tobacco and Intoxicants MoM% | AE1: Transport and Communication | AF1: Transport and Communication MoM%
A2: 2021 | B2: January | C2: 84.666319 | D2: =DATE(Table1[[#This Row],[Year]],MONTH(DATEVALUE(Table1[[#This Row],[Month]]& " 1")),1) -> 44197 | E2: 0 | G2: 2021 | H2: Jan | I2: 151.38889 | J2: 0 | K2: 159.6 | L2: 0 | M2: 159.97949 | N2: 0 | O2: 147.23333 | P2: 0 | Q2: 158.63333 | R2: 0 | S2: 149.86667 | T2: 0 | U2: 157.7 | V2: 0 | W2: 151.8 | X2: 0 | Y2: 156.9 | Z2: 0 | AA2: 150.03333 | AB2: 0 | AC2: 187.63333 | AD2: 0 | AE2: 142.1 | AF2: 0
A3: 2021 | B3: February | C3: 94.067715 | D3: =DATE(Table1[[#This Row],[Year]],MONTH(DATEVALUE(Table1[[#This Row],[Month]]& " 1")),1) -> 44228 | E3: =(Table1[[#This Row],[Value]]-C2)/C2*100 -> 11.104057 | G3: 2021 | H3: Feb | I3: 152.88889 | J3: =(I3-I2)/I2*100 -> 0.99082569 | K3: 159.9 | L3: =(K3-K2)/K2*100 -> 0.18796992 | M3: 157.19487 | N3: =(M3-M2)/M2*100 -> -1.7406078 | O3: 151.96667 | P3: =(O3-O2)/O2*100 -> 3.2148517 | Q3: 160.63333 | R3: =(Q3-Q2)/Q2*100 -> 1.2607691 | S3: 150.73333 | T3: =(S3-S2)/S2*100 -> 0.57829181 | U3: 159.8 | V3: =(U3-U2)/U2*100 -> 1.3316424 | W3: 153.3 | X3: =(W3-W2)/W2*100 -> 0.98814229 | Y3: 155.9 | Z3: =(Y3-Y2)/Y2*100 -> -0.63734863 | AA3: 151.93333 | AB3: =(AA3-AA2)/AA2*100 -> 1.2663852 | AC3: 189.36667 | AD3: =(AC3-AC2)/AC2*100 -> 0.92378753 | AE3: 145.26667 | AF3: =(AE3-AE2)/AE2*100 -> 2.2284776
A4: 2021 | B4: March | C4: 112.87479 | D4: =DATE(Table1[[#This Row],[Year]],MONTH(DATEVALUE(Table1[[#This Row],[Month]]& " 1")),1) -> 44256 | E4: =(Table1[[#This Row],[Value]]-C3)/C3*100 -> 19.993127 | G4: 2021 | H4: Mar | I4: 153.48889 | J4: =(I4-I3)/I3*100 -> 0.39244186 | K4: 160.53333 | L4: =(K4-K3)/K3*100 -> 0.39608088 | M4: 157.16923 | N4: =(M4-M3)/M3*100 -> -0.016311617 | O4: 155.43333 | P4: =(O4-O3)/O3*100 -> 2.281202 | Q4: 161.06667 | R4: =(Q4-Q3)/Q3*100 -> 0.26976551 | S4: 151.06667 | T4: =(S4-S3)/S3*100 -> 0.22114109 | U4: 159.9 | V4: =(U4-U3)/U3*100 -> 0.062578223 | W4: 153.7 | X4: =(W4-W3)/W3*100 -> 0.26092629 | Y4: 153.93333 | Z4: =(Y4-Y3)/Y3*100 -> -1.2614924 | AA4: 153 | AB4: =(AA4-AA3)/AA3*100 -> 0.70206231 | AC4: 189.23333 | AD4: =(AC4-AC3)/AC3*100 -> -0.070410139 | AE4: 146.4 | AF4: =(AE4-AE3)/AE3*100 -> 0.78017439 | AG4: =COUNTIFS(AE2:AE25,">150",AE2:AE25,"<160") -> 10
A5: 2021 | B5: April | C5: 63.396977 | D5: =DATE(Table1[[#This Row],[Year]],MONTH(DATEVALUE(Table1[[#This Row],[Month]]& " 1")),1) -> 44287 | E5: =(Table1[[#This Row],[Value]]-C4)/C4*100 -> -43.834248 | G5: 2021 | H5: Apr | I5: 154.32222 | J5: =(I5-I4)/I4*100 -> 0.54292746 | K5: 160.66667 | L5: =(K5-K4)/K4*100 -> 0.083056478 | M5: 159.05641 | N5: =(M5-M4)/M4*100 -> 1.2007309 | O5: 155.5 | P5: =(O5-O4)/O4*100 -> 0.042890843 | Q5: 161.7 | R5: =(Q5-Q4)/Q4*100 -> 0.39321192 | S5: 151.63333 | T5: =(S5-S4)/S4*100 -> 0.37511033 | U5: 161.4 | V5: =(U5-U4)/U4*100 -> 0.9380863 | W5: 154.3 | X5: =(W5-W4)/W4*100 -> 0.39037085 | Y5: 155.53333 | Z5: =(Y5-Y4)/Y4*100 -> 1.039411 | AA5: 153.63333 | AB5: =(AA5-AA4)/AA4*100 -> 0.41394336 | AC5: 190 | AD5: =(AC5-AC4)/AC4*100 -> 0.40514356 | AE5: 146.8 | AF5: =(AE5-AE4)/AE4*100 -> 0.27322404
A6: 2021 | B6: May | C6: 66.953085 | D6: =DATE(Table1[[#This Row],[Year]],MONTH(DATEVALUE(Table1[[#This Row],[Month]]& " 1")),1) -> 44317 | E6: =(Table1[[#This Row],[Value]]-C5)/C5*100 -> 5.6092712 | G6: 2021 | H6: May | I6: 157.27778 | J6: =(I6-I5)/I5*100 -> 1.9151847 | K6: 161.8 | L6: =(K6-K5)/K5*100 -> 0.70539419 | M6: 162.19744 | N6: =(M6-M5)/M5*100 -> 1.9747872 | O6: 158.86667 | P6: =(O6-O5)/O5*100 -> 2.1650589 | Q6: 165.1 | R6: =(Q6-Q5)/Q5*100 -> 2.1026592 | S6: 154.53333 | T6: =(S6-S5)/S5*100 -> 1.9125082 | U6: 161.6 | V6: =(U6-U5)/U5*100 -> 0.12391574 | W6: 156.73333 | X6: =(W6-W5)/W5*100 -> 1.5770145 | Y6: 158.46667 | Z6: =(Y6-Y5)/Y5*100 -> 1.8859837 | AA6: 156.13333 | AB6: =(AA6-AA5)/AA5*100 -> 1.627251 | AC6: 193.23333 | AD6: =(AC6-AC5)/AC5*100 -> 1.7017544 | AE6: 149.03333 | AF6: =(AE6-AE5)/AE5*100 -> 1.5213442
A7: 2021 | B7: June | C7: 71.982647 | D7: =DATE(Table1[[#This Row],[Year]],MONTH(DATEVALUE(Table1[[#This Row],[Month]]& " 1")),1) -> 44348 | E7: =(Table1[[#This Row],[Value]]-C6)/C6*100 -> 7.51207 | G7: 2021 | H7: Jun | I7: 157.45556 | J7: =(I7-I6)/I6*100 -> 0.11303426 | K7: 162.2 | L7: =(K7-K6)/K6*100 -> 0.24721879 | M7: 164.37692 | N7: =(M7-M6)/M6*100 -> 1.3437248 | O7: 159.33333 | P7: =(O7-O6)/O6*100 -> 0.29374738 | Q7: 165.6 | R7: =(Q7-Q6)/Q6*100 -> 0.30284676 | S7: 154.6 | T7: =(S7-S6)/S6*100 -> 0.043140638 | U7: 160.5 | V7: =(U7-U6)/U6*100 -> -0.68069307 | W7: 157.5 | X7: =(W7-W6)/W6*100 -> 0.48915355 | Y7: 158.73333 | Z7: =(Y7-Y6)/Y6*100 -> 0.16827934 | AA7: 155.33333 | AB7: =(AA7-AA6)/AA6*100 -> -0.51238258 | AC7: 191.83333 | AD7: =(AC7-AC6)/AC6*100 -> -0.72451268 | AE7: 150.8 | AF7: =(AE7-AE6)/AE6*100 -> 1.1854171
A8: 2021 | B8: July | C8: 73.539061 | D8: =DATE(Table1[[#This Row],[Year]],MONTH(DATEVALUE(Table1[[#This Row],[Month]]& " 1")),1) -> 44378 | E8: =(Table1[[#This Row],[Value]]-C7)/C7*100 -> 2.1622059 | G8: 2021 | H8: Jul | I8: 158.33333 | J8: =(I8-I7)/I7*100 -> 0.55747654 | K8: 163.56667 | L8: =(K8-K7)/K7*100 -> 0.84258118 | M8: 165.41538 | N8: =(M8-M7)/M7*100 -> 0.63175628 | O8: 160.3 | P8: =(O8-O7)/O7*100 -> 0.60669456 | Q8: 166.3 | R8: =(Q8-Q7)/Q7*100 -> 0.42270531 | S8: 155.6 | T8: =(S8-S7)/S7*100 -> 0.64683053 | U8: 161.5 | V8: =(U8-U7)/U7*100 -> 0.62305296 | W8: 158.93333 | X8: =(W8-W7)/W7*100 -> 0.91005291 | Y8: 160.03333 | Z8: =(Y8-Y7)/Y7*100 -> 0.81898362 | AA8: 155.73333 | AB8: =(AA8-AA7)/AA7*100 -> 0.25751073 | AC8: 192.13333 | AD8: =(AC8-AC7)/AC7*100 -> 0.15638575 | AE8: 153.23333 | AF8: =(AE8-AE7)/AE7*100 -> 1.6136163
A9: 2021 | B9: August | C9: 69.804724 | D9: =DATE(Table1[[#This Row],[Year]],MONTH(DATEVALUE(Table1[[#This Row],[Month]]& " 1")),1) -> 44409 | E9: =(Table1[[#This Row],[Value]]-C8)/C8*100 -> -5.0780307 | G9: 2021 | H9: Aug | I9: 159.95556 | J9: =(I9-I8)/I8*100 -> 1.0245614 | K9: 163.9 | L9: =(K9-K8)/K8*100 -> 0.2037905 | M9: 164.88974 | N9: =(M9-M8)/M8*100 -> -0.31777034 | O9: 162.13333 | P9: =(O9-O8)/O8*100 -> 1.1436889 | Q9: 167.43333 | R9: =(Q9-Q8)/Q8*100 -> 0.6814993 | S9: 157.2 | T9: =(S9-S8)/S8*100 -> 1.0282776 | U9: 162.1 | V9: =(U9-U8)/U8*100 -> 0.37151703 | W9: 159.76667 | X9: =(W9-W8)/W8*100 -> 0.52432886 | Y9: 159.96667 | Z9: =(Y9-Y8)/Y8*100 -> -0.041657988 | AA9: 157.46667 | AB9: =(AA9-AA8)/AA8*100 -> 1.1130137 | AC9: 192.93333 | AD9: =(AC9-AC8)/AC8*100 -> 0.41637752 | AE9: 154.03333 | AF9: =(AE9-AE8)/AE8*100 -> 0.52207962
